Workbook

Sheet RencanaPengujian
A1: Nama KAP | C1: : | D1: Syarief, Wibawa & Rekan
A2: Nama AP | C2: : | D2: Budi T. Wibawa
A3: Nama Klien | C3: : | D3: PT YKL Indonesia
A4: Alamat Klien | C4: : | D4: Jalan Millenium IV Blok A 24/7, Kawasan Industri Millenium, Peusar/Panongan, Tangerang
A5: Tahun Buku | C5: : | D5: Audit Laporan Keuangan untuk Tahun yang Berakhir 31 Desember 2024
A6: Indeks KKA | C6: : | D6: RR.RPH
A7: Nama Indeks | C7: : | D7: Rencana Pengujian dan Hasilnya
A8: Periode | C8: : | D8: Current | G8: 6
B10: RENCANA PENGUJIAN DAN HASILNYA
B12: Simpulan | D12: Rencana pengujian dan hasilnya sudah memadai
D14: Jelaskan dasar kesimpulan di atas
B15: Status KKA
B16: Completed
A18: Trial Balance | G18: Current | H18: Periksa | K18: Pengujian | O18: Risk Analysis | W18: Sampling | Y18: Hasil Pengujian
A19: Header | D19: no_N | E19: no_O | F19: Nama_akun | G19: =IF($D$8="Interim",TB_audited!G2,TB_audited!E2) -> 45657 | H19: AP | I19: ToD | J19: I/YE | K19: Periksa Langsung Ya/Tdk | L19: Sampling Ya/Tdk | M19: Populasi (Rp) | N19: Sampling (Rp) | O19: M/TM | P19: ROMM | Q19: Significant Account | R19: AP Result H/M/N | S19: Performance Materiality | T19: Risk Factor Adjutment | U19: Specific Materiality | V19: Confidence Factor | W19: Sample Interval | X19: Jumlah Sample | Y19: Lebih Salah Saji | Z19: Kurang Salah Saji | AA19: Status | AB19: ToD
A20: =TB_audited!A3 -> Trade receivable | D20: =TB_audited!B3 -> 11201 | E20: =TB_audited!C3 -> 100/0000 | F20: =TB_audited!D3 -> TRADE DEBTORS - IDR | G20: =IF($D$8="Interim",TB_audited!G3,TB_audited!E3) -> 18567911215 | H20: =IFERROR(VLOOKUP($A20,RA_result!$B$3:$N$62,11,0),"") | I20: =IFERROR(VLOOKUP($A20,RA_result!$B$3:$N$62,12,0),"") -> Ya | J20: =IFERROR(VLOOKUP($A20,RA_result!$B$3:$N$62,13,0),"") -> YE | K20: Tidak | L20: Ya | M20: 9728145173 | N20: =G20-M20 -> 8839766042 | O20: =IFERROR(VLOOKUP($A20,RA_result!$B$3:$N$62,7,0),"") -> M | P20: =IFERROR(VLOOKUP($A20,RA_result!$B$3:$N$62,9,0),"") -> M | Q20: =IFERROR(VLOOKUP($A20,RA_result!$B$3:$N$62,10,0),"") | R20: N | S20: =IFERROR(VLOOKUP($A20,RA_result!$B$3:$N$62,4,0),"") -> 1.0535504e+09 | T20: 0.9 | U20: =IFERROR(IF(VLOOKUP($A20,RA_result!$B$3:$N$62,6,0)="",S20*T20,VLOOKUP($A20,RA_result!$B$3:$N$62,6,0)),"") -> 9.4819535e+08 | V20: 1.9 | W20: =IFERROR((S20*30%)/V20,0) -> 1.6635006e+08 | X20: =IFERROR(N20/W20,0) -> 53.139542 | Y20: 2.6519298e+08 | Z20: -2.6519298e+08 | AA20: =IF(OR(U20="",Y20="",Z20=""),"",IF(AND(U20>Y20,-U20<Z20),"Ok","Not Ok")) -> Ok
A21: =TB_audited!A4 -> Trade receivable | D21: =TB_audited!B4 -> 11202 | E21: =TB_audited!C4 -> 100/0001 | F21: =TB_audited!D4 -> Provision of Allowance Bad Debts | G21: =IF($D$8="Interim",TB_audited!G4,TB_audited!E4) -> -2286452814 | H21: =IFERROR(VLOOKUP($A21,RA_result!$B$3:$N$62,11,0),"") | I21: =IFERROR(VLOOKUP($A21,RA_result!$B$3:$N$62,12,0),"") -> Ya | J21: =IFERROR(VLOOKUP($A21,RA_result!$B$3:$N$62,13,0),"") -> YE | K21: Ya | L21: Tidak | M21: -2286452814 | N21: =G21-M21 -> 0 | O21: =IFERROR(VLOOKUP($A21,RA_result!$B$3:$N$62,7,0),"") -> M | P21: =IFERROR(VLOOKUP($A21,RA_result!$B$3:$N$62,9,0),"") -> M | Q21: =IFERROR(VLOOKUP($A21,RA_result!$B$3:$N$62,10,0),"") | R21: N | S21: =IFERROR(VLOOKUP($A21,RA_result!$B$3:$N$62,4,0),"") -> 1.0535504e+09 | T21: 0.65 | U21: =IFERROR(IF(VLOOKUP($A21,RA_result!$B$3:$N$62,6,0)="",S21*T21,VLOOKUP($A21,RA_result!$B$3:$N$62,6,0)),"") -> 6.8480776e+08 | V21: 1.3 | W21: =IFERROR((S21*30%)/V21,0) -> 2.4312701e+08 | X21: =IFERROR(N21/W21,0) -> 0 | AA21: =IF(OR(U21="",Y21="",Z21=""),"",IF(AND(U21>Y21,-U21<Z21),"Ok","Not Ok"))
A22: =TB_audited!A5 -> Other current asset | D22: =TB_audited!B5 -> 11901 | E22: =TB_audited!C5 -> 105/0010 | F22: =TB_audited!D5 -> YKL ENGINEERING SDN. BHD. (PJS) | G22: =IF($D$8="Interim",TB_audited!G5,TB_audited!E5) -> 0 | H22: =IFERROR(VLOOKUP($A22,RA_result!$B$3:$N$62,11,0),"") | I22: =IFERROR(VLOOKUP($A22,RA_result!$B$3:$N$62,12,0),"") | J22: =IFERROR(VLOOKUP($A22,RA_result!$B$3:$N$62,13,0),"") | M22: 0 | N22: =G22-M22 -> 0 | O22: =IFERROR(VLOOKUP($A22,RA_result!$B$3:$N$62,7,0),"") -> TM | P22: =IFERROR(VLOOKUP($A22,RA_result!$B$3:$N$62,9,0),"") -> L | Q22: =IFERROR(VLOOKUP($A22,RA_result!$B$3:$N$62,10,0),"") | R22: N | S22: =IFERROR(VLOOKUP($A22,RA_result!$B$3:$N$62,4,0),"") -> 1.0535504e+09 | T22: 0.9 | U22: =IFERROR(IF(VLOOKUP($A22,RA_result!$B$3:$N$62,6,0)="",S22*T22,VLOOKUP($A22,RA_result!$B$3:$N$62,6,0)),"") -> 9.4819535e+08 | W22: =IFERROR((S22*30%)/V22,0) -> 0 | X22: =IFERROR(N22/W22,0) -> 0 | AA22: =IF(OR(U22="",Y22="",Z22=""),"",IF(AND(U22>Y22,-U22<Z22),"Ok","Not Ok"))
A23: =TB_audited!A6 -> Other current asset | D23: =TB_audited!B6 -> 11902 | E23: =TB_audited!C6 -> 105/0060 | F23: =TB_audited!D6 -> PT. KMT ENGINEERING NUSANTARA (PJS) | G23: =IF($D$8="Interim",TB_audited!G6,TB_audited!E6) -> 0 | H23: =IFERROR(VLOOKUP($A23,RA_result!$B$3:$N$62,11,0),"") | I23: =IFERROR(VLOOKUP($A23,RA_result!$B$3:$N$62,12,0),"") | J23: =IFERROR(VLOOKUP($A23,RA_result!$B$3:$N$62,13,0),"") | M23: 0 | N23: =G23-M23 -> 0 | O23: =IFERROR(VLOOKUP($A23,RA_result!$B$3:$N$62,7,0),"") -> TM | P23: =IFERROR(VLOOKUP($A23,RA_result!$B$3:$N$62,9,0),"") -> L | Q23: =IFERROR(VLOOKUP($A23,RA_result!$B$3:$N$62,10,0),"") | R23: N | S23: =IFERROR(VLOOKUP($A23,RA_result!$B$3:$N$62,4,0),"") -> 1.0535504e+09 | T23: 0.9 | U23: =IFERROR(IF(VLOOKUP($A23,RA_result!$B$3:$N$62,6,0)="",S23*T23,VLOOKUP($A23,RA_result!$B$3:$N$62,6,0)),"") -> 9.4819535e+08 | W23: =IFERROR((S23*30%)/V23,0) -> 0 | X23: =IFERROR(N23/W23,0) -> 0 | AA23: =IF(OR(U23="",Y23="",Z23=""),"",IF(AND(U23>Y23,-U23<Z23),"Ok","Not Ok"))
A24: =TB_audited!A7 -> Cash and cash equivalent | D24: =TB_audited!B7 -> 11101 | E24: =TB_audited!C7 -> 110/0000 | F24: =TB_audited!D7 -> CASH IN HAND | G24: =IF($D$8="Interim",TB_audited!G7,TB_audited!E7) -> 23836004 | H24: =IFERROR(VLOOKUP($A24,RA_result!$B$3:$N$62,11,0),"") | I24: =IFERROR(VLOOKUP($A24,RA_result!$B$3:$N$62,12,0),"") -> Ya | J24: =IFERROR(VLOOKUP($A24,RA_result!$B$3:$N$62,13,0),"") -> YE | K24: Ya | L24: Tidak | M24: 23836004 | N24: =G24-M24 -> 0 | O24: =IFERROR(VLOOKUP($A24,RA_result!$B$3:$N$62,7,0),"") -> M | P24: =IFERROR(VLOOKUP($A24,RA_result!$B$3:$N$62,9,0),"") -> L | Q24: =IFERROR(VLOOKUP($A24,RA_result!$B$3:$N$62,10,0),"") | R24: N | S24: =IFERROR(VLOOKUP($A24,RA_result!$B$3:$N$62,4,0),"") -> 1.0535504e+09 | T24: 0.9 | U24: =IFERROR(IF(VLOOKUP($A24,RA_result!$B$3:$N$62,6,0)="",S24*T24,VLOOKUP($A24,RA_result!$B$3:$N$62,6,0)),"") -> 9.4819535e+08 | V24: 1.3 | W24: =IFERROR((S24*30%)/V24,0) -> 2.4312701e+08 | X24: =IFERROR(N24/W24,0) -> 0 | AA24: =IF(OR(U24="",Y24="",Z24=""),"",IF(AND(U24>Y24,-U24<Z24),"Ok","Not Ok"))
A25: =TB_audited!A8 -> Cash and cash equivalent | D25: =TB_audited!B8 -> 11102 | E25: =TB_audited!C8 -> 120/0030 | F25: =TB_audited!D8 -> CASH AT BANK-BCA (2ND) A/C : 764BCA (2ND) A/C : 7640669998 IDR | G25: =IF($D$8="Interim",TB_audited!G8,TB_audited!E8) -> 21825626 | H25: =IFERROR(VLOOKUP($A25,RA_result!$B$3:$N$62,11,0),"") | I25: =IFERROR(VLOOKUP($A25,RA_result!$B$3:$N$62,12,0),"") -> Ya | J25: =IFERROR(VLOOKUP($A25,RA_result!$B$3:$N$62,13,0),"") -> YE | K25: Ya | L25: Tidak | M25: 21825626 | N25: =G25-M25 -> 0 | O25: =IFERROR(VLOOKUP($A25,RA_result!$B$3:$N$62,7,0),"") -> M | P25: =IFERROR(VLOOKUP($A25,RA_result!$B$3:$N$62,9,0),"") -> L | Q25: =IFERROR(VLOOKUP($A25,RA_result!$B$3:$N$62,10,0),"") | R25: N | S25: =IFERROR(VLOOKUP($A25,RA_result!$B$3:$N$62,4,0),"") -> 1.0535504e+09 | T25: 0.9 | U25: =IFERROR(IF(VLOOKUP($A25,RA_result!$B$3:$N$62,6,0)="",S25*T25,VLOOKUP($A25,RA_result!$B$3:$N$62,6,0)),"") -> 9.4819535e+08 | V25: 1.3 | W25: =IFERROR((S25*30%)/V25,0) -> 2.4312701e+08 | X25: =IFERROR(N25/W25,0) -> 0 | AA25: =IF(OR(U25="",Y25="",Z25=""),"",IF(AND(U25>Y25,-U25<Z25),"Ok","Not Ok"))
A26: =TB_audited!A9 -> Cash and cash equivalent | D26: =TB_audited!B9 -> 11103 | E26: =TB_audited!C9 -> 120/0040 | F26: =TB_audited!D9 -> CASH AT BANK-BCA (EMG) A/C : 764BCA (EMG) A/C : 7640669599 IDR | G26: =IF($D$8="Interim",TB_audited!G9,TB_audited!E9) -> 2.487905e+08 | H26: =IFERROR(VLOOKUP($A26,RA_result!$B$3:$N$62,11,0),"") | I26: =IFERROR(VLOOKUP($A26,RA_result!$B$3:$N$62,12,0),"") -> Ya | J26: =IFERROR(VLOOKUP($A26,RA_result!$B$3:$N$62,13,0),"") -> YE | K26: Ya | L26: Tidak | M26: 2.487905e+08 | N26: =G26-M26 -> 0 | O26: =IFERROR(VLOOKUP($A26,RA_result!$B$3:$N$62,7,0),"") -> M | P26: =IFERROR(VLOOKUP($A26,RA_result!$B$3:$N$62,9,0),"") -> L | Q26: =IFERROR(VLOOKUP($A26,RA_result!$B$3:$N$62,10,0),"") | R26: N | S26: =IFERROR(VLOOKUP($A26,RA_result!$B$3:$N$62,4,0),"") -> 1.0535504e+09 | T26: 0.9 | U26: =IFERROR(IF(VLOOKUP($A26,RA_result!$B$3:$N$62,6,0)="",S26*T26,VLOOKUP($A26,RA_result!$B$3:$N$62,6,0)),"") -> 9.4819535e+08 | V26: 1.3 | W26: =IFERROR((S26*30%)/V26,0) -> 2.4312701e+08 | X26: =IFERROR(N26/W26,0) -> 0 | AA26: =IF(OR(U26="",Y26="",Z26=""),"",IF(AND(U26>Y26,-U26<Z26),"Ok","Not Ok"))
A27: =TB_audited!A10 -> Cash and cash equivalent | D27: =TB_audited!B10 -> 11104 | E27: =TB_audited!C10 -> 120/0050 | F27: =TB_audited!D10 -> CASH AT BANK-MANDIRI A/C : 118003MANDIRI A/C : 1180033355677 IDR | G27: =IF($D$8="Interim",TB_audited!G10,TB_audited!E10) -> 3.3120579e+10 | H27: =IFERROR(VLOOKUP($A27,RA_result!$B$3:$N$62,11,0),"") | I27: =IFERROR(VLOOKUP($A27,RA_result!$B$3:$N$62,12,0),"") -> Ya | J27: =IFERROR(VLOOKUP($A27,RA_result!$B$3:$N$62,13,0),"") -> YE | K27: Ya | L27: Tidak | M27: 3.3120579e+10 | N27: =G27-M27 -> 0 | O27: =IFERROR(VLOOKUP($A27,RA_result!$B$3:$N$62,7,0),"") -> M | P27: =IFERROR(VLOOKUP($A27,RA_result!$B$3:$N$62,9,0),"") -> L | Q27: =IFERROR(VLOOKUP($A27,RA_result!$B$3:$N$62,10,0),"") | R27: N | S27: =IFERROR(VLOOKUP($A27,RA_result!$B$3:$N$62,4,0),"") -> 1.0535504e+09 | T27: 0.9 | U27: =IFERROR(IF(VLOOKUP($A27,RA_result!$B$3:$N$62,6,0)="",S27*T27,VLOOKUP($A27,RA_result!$B$3:$N$62,6,0)),"") -> 9.4819535e+08 | V27: 1.3 | W27: =IFERROR((S27*30%)/V27,0) -> 2.4312701e+08 | X27: =IFERROR(N27/W27,0) -> 0 | AA27: =IF(OR(U27="",Y27="",Z27=""),"",IF(AND(U27>Y27,-U27<Z27),"Ok","Not Ok"))
A28: =TB_audited!A11 -> Cash and cash equivalent | D28: =TB_audited!B11 -> 11105 | E28: =TB_audited!C11 -> 120/0100 | F28: =TB_audited!D11 -> CASH AT BANK-MANDIRI A/C : 1180007MANDIRI A/C : 1180007832388 USD2 | G28: =IF($D$8="Interim",TB_audited!G11,TB_audited!E11) -> 0 | H28: =IFERROR(VLOOKUP($A28,RA_result!$B$3:$N$62,11,0),"") | I28: =IFERROR(VLOOKUP($A28,RA_result!$B$3:$N$62,12,0),"") -> Ya | J28: =IFERROR(VLOOKUP($A28,RA_result!$B$3:$N$62,13,0),"") -> YE | K28: Ya | L28: Tidak | M28: 0 | N28: =G28-M28 -> 0 | O28: =IFERROR(VLOOKUP($A28,RA_result!$B$3:$N$62,7,0),"") -> M | P28: =IFERROR(VLOOKUP($A28,RA_result!$B$3:$N$62,9,0),"") -> L | Q28: =IFERROR(VLOOKUP($A28,RA_result!$B$3:$N$62,10,0),"") | R28: N | S28: =IFERROR(VLOOKUP($A28,RA_result!$B$3:$N$62,4,0),"") -> 1.0535504e+09 | T28: 0.9 | U28: =IFERROR(IF(VLOOKUP($A28,RA_result!$B$3:$N$62,6,0)="",S28*T28,VLOOKUP($A28,RA_result!$B$3:$N$62,6,0)),"") -> 9.4819535e+08 | V28: 1.3 | W28: =IFERROR((S28*30%)/V28,0) -> 2.4312701e+08 | X28: =IFERROR(N28/W28,0) -> 0 | AA28: =IF(OR(U28="",Y28="",Z28=""),"",IF(AND(U28>Y28,-U28<Z28),"Ok","Not Ok"))
A29: =TB_audited!A12 -> Cash and cash equivalent | D29: =TB_audited!B12 -> 11106 | E29: =TB_audited!C12 -> 120/0140 | F29: =TB_audited!D12 -> CASH AT BANK-BNI A/C:855771775 | G29: =IF($D$8="Interim",TB_audited!G12,TB_audited!E12) -> 905130602 | H29: =IFERROR(VLOOKUP($A29,RA_result!$B$3:$N$62,11,0),"") | I29: =IFERROR(VLOOKUP($A29,RA_result!$B$3:$N$62,12,0),"") -> Ya | J29: =IFERROR(VLOOKUP($A29,RA_result!$B$3:$N$62,13,0),"") -> YE | K29: Ya | L29: Tidak | M29: 905130602 | N29: =G29-M29 -> 0 | O29: =IFERROR(VLOOKUP($A29,RA_result!$B$3:$N$62,7,0),"") -> M | P29: =IFERROR(VLOOKUP($A29,RA_result!$B$3:$N$62,9,0),"") -> L | Q29: =IFERROR(VLOOKUP($A29,RA_result!$B$3:$N$62,10,0),"") | R29: N | S29: =IFERROR(VLOOKUP($A29,RA_result!$B$3:$N$62,4,0),"") -> 1.0535504e+09 | T29: 0.9 | U29: =IFERROR(IF(VLOOKUP($A29,RA_result!$B$3:$N$62,6,0)="",S29*T29,VLOOKUP($A29,RA_result!$B$3:$N$62,6,0)),"") -> 9.4819535e+08 | V29: 1.3 | W29: =IFERROR((S29*30%)/V29,0) -> 2.4312701e+08 | X29: =IFERROR(N29/W29,0) -> 0 | AA29: =IF(OR(U29="",Y29="",Z29=""),"",IF(AND(U29>Y29,-U29<Z29),"Ok","Not Ok"))
A30: =TB_audited!A13 -> Inventory | D30: =TB_audited!B13 -> 11601 | E30: =TB_audited!C13 -> 126/1000 | F30: =TB_audited!D13 -> INVENTORY-MACHINE | G30: =IF($D$8="Interim",TB_audited!G13,TB_audited!E13) -> 333000000 | H30: =IFERROR(VLOOKUP($A30,RA_result!$B$3:$N$62,11,0),"") | I30: =IFERROR(VLOOKUP($A30,RA_result!$B$3:$N$62,12,0),"") -> Ya | J30: =IFERROR(VLOOKUP($A30,RA_result!$B$3:$N$62,13,0),"") -> YE | K30: Tidak | L30: Ya | M30: 333000000 | N30: =G30-M30 -> 0 | O30: =IFERROR(VLOOKUP($A30,RA_result!$B$3:$N$62,7,0),"") -> M | P30: =IFERROR(VLOOKUP($A30,RA_result!$B$3:$N$62,9,0),"") -> L | Q30: =IFERROR(VLOOKUP($A30,RA_result!$B$3:$N$62,10,0),"") | R30: N | S30: =IFERROR(VLOOKUP($A30,RA_result!$B$3:$N$62,4,0),"") -> 1.0535504e+09 | T30: 0.9 | U30: =IFERROR(IF(VLOOKUP($A30,RA_result!$B$3:$N$62,6,0)="",S30*T30,VLOOKUP($A30,RA_result!$B$3:$N$62,6,0)),"") -> 9.4819535e+08 | V30: 1.3 | W30: =IFERROR((S30*30%)/V30,0) -> 2.4312701e+08 | X30: =IFERROR(N30/W30,0) -> 0 | AA30: =IF(OR(U30="",Y30="",Z30=""),"",IF(AND(U30>Y30,-U30<Z30),"Ok","Not Ok"))
A31: =TB_audited!A14 -> Inventory | D31: =TB_audited!B14 -> 11602 | E31: =TB_audited!C14 -> 126/2000 | F31: =TB_audited!D14 -> INVENTORY-SPAREPARTS | G31: =IF($D$8="Interim",TB_audited!G14,TB_audited!E14) -> 1.3896503e+10 | H31: =IFERROR(VLOOKUP($A31,RA_result!$B$3:$N$62,11,0),"") | I31: =IFERROR(VLOOKUP($A31,RA_result!$B$3:$N$62,12,0),"") -> Ya | J31: =IFERROR(VLOOKUP($A31,RA_result!$B$3:$N$62,13,0),"") -> YE | K31: Ya | L31: Tidak | M31: 1.3896503e+10 | N31: =G31-M31 -> 0 | O31: =IFERROR(VLOOKUP($A31,RA_result!$B$3:$N$62,7,0),"") -> M | P31: =IFERROR(VLOOKUP($A31,RA_result!$B$3:$N$62,9,0),"") -> L | Q31: =IFERROR(VLOOKUP($A31,RA_result!$B$3:$N$62,10,0),"") | R31: N | S31: =IFERROR(VLOOKUP($A31,RA_result!$B$3:$N$62,4,0),"") -> 1.0535504e+09 | T31: 0.9 | U31: =IFERROR(IF(VLOOKUP($A31,RA_result!$B$3:$N$62,6,0)="",S31*T31,VLOOKUP($A31,RA_result!$B$3:$N$62,6,0)),"") -> 9.4819535e+08 | V31: 1.3 | W31: =IFERROR((S31*30%)/V31,0) -> 2.4312701e+08 | X31: =IFERROR(N31/W31,0) -> 0 | AA31: =IF(OR(U31="",Y31="",Z31=""),"",IF(AND(U31>Y31,-U31<Z31),"Ok","Not Ok"))
A32: =TB_audited!A15 -> Other current asset | D32: =TB_audited!B15 -> 11903 | E32: =TB_audited!C15 -> 130/0060 | F32: =TB_audited!D15 -> ADE IRAWAN | G32: =IF($D$8="Interim",TB_audited!G15,TB_audited!E15) -> 1500000 | H32: =IFERROR(VLOOKUP($A32,RA_result!$B$3:$N$62,11,0),"") | I32: =IFERROR(VLOOKUP($A32,RA_result!$B$3:$N$62,12,0),"") | J32: =IFERROR(VLOOKUP($A32,RA_result!$B$3:$N$62,13,0),"") | M32: 1500000 | N32: =G32-M32 -> 0 | O32: =IFERROR(VLOOKUP($A32,RA_result!$B$3:$N$62,7,0),"") -> TM | P32: =IFERROR(VLOOKUP($A32,RA_result!$B$3:$N$62,9,0),"") -> L | Q32: =IFERROR(VLOOKUP($A32,RA_result!$B$3:$N$62,10,0),"") | R32: N | S32: =IFERROR(VLOOKUP($A32,RA_result!$B$3:$N$62,4,0),"") -> 1.0535504e+09 | T32: 0.9 | U32: =IFERROR(IF(VLOOKUP($A32,RA_result!$B$3:$N$62,6,0)="",S32*T32,VLOOKUP($A32,RA_result!$B$3:$N$62,6,0)),"") -> 9.4819535e+08 | W32: =IFERROR((S32*30%)/V32,0) -> 0 | X32: =IFERROR(N32/W32,0) -> 0 | AA32: =IF(OR(U32="",Y32="",Z32=""),"",IF(AND(U32>Y32,-U32<Z32),"Ok","Not Ok"))
A33: =TB_audited!A16 -> Other current asset | D33: =TB_audited!B16 -> 11904 | E33: =TB_audited!C16 -> 130/0090 | F33: =TB_audited!D16 -> NURDIN ANDRIANSYAH | G33: =IF($D$8="Interim",TB_audited!G16,TB_audited!E16) -> 0 | H33: =IFERROR(VLOOKUP($A33,RA_result!$B$3:$N$62,11,0),"") | I33: =IFERROR(VLOOKUP($A33,RA_result!$B$3:$N$62,12,0),"") | J33: =IFERROR(VLOOKUP($A33,RA_result!$B$3:$N$62,13,0),"") | M33: 0 | N33: =G33-M33 -> 0 | O33: =IFERROR(VLOOKUP($A33,RA_result!$B$3:$N$62,7,0),"") -> TM | P33: =IFERROR(VLOOKUP($A33,RA_result!$B$3:$N$62,9,0),"") -> L | Q33: =IFERROR(VLOOKUP($A33,RA_result!$B$3:$N$62,10,0),"") | R33: N | S33: =IFERROR(VLOOKUP($A33,RA_result!$B$3:$N$62,4,0),"") -> 1.0535504e+09 | T33: 0.9 | U33: =IFERROR(IF(VLOOKUP($A33,RA_result!$B$3:$N$62,6,0)="",S33*T33,VLOOKUP($A33,RA_result!$B$3:$N$62,6,0)),"") -> 9.4819535e+08 | W33: =IFERROR((S33*30%)/V33,0) -> 0 | X33: =IFERROR(N33/W33,0) -> 0 | AA33: =IF(OR(U33="",Y33="",Z33=""),"",IF(AND(U33>Y33,-U33<Z33),"Ok","Not Ok"))
A34: =TB_audited!A17 -> Other current asset | D34: =TB_audited!B17 -> 11905 | E34: =TB_audited!C17 -> 130/0120 | F34: =TB_audited!D17 -> HUSNI APENDI | G34: =IF($D$8="Interim",TB_audited!G17,TB_audited!E17) -> 0 | H34: =IFERROR(VLOOKUP($A34,RA_result!$B$3:$N$62,11,0),"") | I34: =IFERROR(VLOOKUP($A34,RA_result!$B$3:$N$62,12,0),"") | J34: =IFERROR(VLOOKUP($A34,RA_result!$B$3:$N$62,13,0),"") | M34: 0 | N34: =G34-M34 -> 0 | O34: =IFERROR(VLOOKUP($A34,RA_result!$B$3:$N$62,7,0),"") -> TM | P34: =IFERROR(VLOOKUP($A34,RA_result!$B$3:$N$62,9,0),"") -> L | Q34: =IFERROR(VLOOKUP($A34,RA_result!$B$3:$N$62,10,0),"") | R34: N | S34: =IFERROR(VLOOKUP($A34,RA_result!$B$3:$N$62,4,0),"") -> 1.0535504e+09 | T34: 0.9 | U34: =IFERROR(IF(VLOOKUP($A34,RA_result!$B$3:$N$62,6,0)="",S34*T34,VLOOKUP($A34,RA_result!$B$3:$N$62,6,0)),"") -> 9.4819535e+08 | W34: =IFERROR((S34*30%)/V34,0) -> 0 | X34: =IFERROR(N34/W34,0) -> 0 | AA34: =IF(OR(U34="",Y34="",Z34=""),"",IF(AND(U34>Y34,-U34<Z34),"Ok","Not Ok"))
A35: =TB_audited!A18 -> Other current asset | D35: =TB_audited!B18 -> 11906 | E35: =TB_audited!C18 -> 130/0180 | F35: =TB_audited!D18 -> OKTA SANDRIAWAN | G35: =IF($D$8="Interim",TB_audited!G18,TB_audited!E18) -> 0 | H35: =IFERROR(VLOOKUP($A35,RA_result!$B$3:$N$62,11,0),"") | I35: =IFERROR(VLOOKUP($A35,RA_result!$B$3:$N$62,12,0),"") | J35: =IFERROR(VLOOKUP($A35,RA_result!$B$3:$N$62,13,0),"") | M35: 0 | N35: =G35-M35 -> 0 | O35: =IFERROR(VLOOKUP($A35,RA_result!$B$3:$N$62,7,0),"") -> TM | P35: =IFERROR(VLOOKUP($A35,RA_result!$B$3:$N$62,9,0),"") -> L | Q35: =IFERROR(VLOOKUP($A35,RA_result!$B$3:$N$62,10,0),"") | R35: N | S35: =IFERROR(VLOOKUP($A35,RA_result!$B$3:$N$62,4,0),"") -> 1.0535504e+09 | T35: 0.9 | U35: =IFERROR(IF(VLOOKUP($A35,RA_result!$B$3:$N$62,6,0)="",S35*T35,VLOOKUP($A35,RA_result!$B$3:$N$62,6,0)),"") -> 9.4819535e+08 | W35: =IFERROR((S35*30%)/V35,0) -> 0 | X35: =IFERROR(N35/W35,0) -> 0 | AA35: =IF(OR(U35="",Y35="",Z35=""),"",IF(AND(U35>Y35,-U35<Z35),"Ok","Not Ok"))
A36: =TB_audited!A19 -> Other current asset | D36: =TB_audited!B19 -> 11907 | E36: =TB_audited!C19 -> 130/0200 | F36: =TB_audited!D19 -> IRWAN YUWONO | G36: =IF($D$8="Interim",TB_audited!G19,TB_audited!E19) -> 2400000 | H36: =IFERROR(VLOOKUP($A36,RA_result!$B$3:$N$62,11,0),"") | I36: =IFERROR(VLOOKUP($A36,RA_result!$B$3:$N$62,12,0),"") | J36: =IFERROR(VLOOKUP($A36,RA_result!$B$3:$N$62,13,0),"") | M36: 2400000 | N36: =G36-M36 -> 0 | O36: =IFERROR(VLOOKUP($A36,RA_result!$B$3:$N$62,7,0),"") -> TM | P36: =IFERROR(VLOOKUP($A36,RA_result!$B$3:$N$62,9,0),"") -> L | Q36: =IFERROR(VLOOKUP($A36,RA_result!$B$3:$N$62,10,0),"") | R36: N | S36: =IFERROR(VLOOKUP($A36,RA_result!$B$3:$N$62,4,0),"") -> 1.0535504e+09 | T36: 0.9 | U36: =IFERROR(IF(VLOOKUP($A36,RA_result!$B$3:$N$62,6,0)="",S36*T36,VLOOKUP($A36,RA_result!$B$3:$N$62,6,0)),"") -> 9.4819535e+08 | W36: =IFERROR((S36*30%)/V36,0) -> 0 | X36: =IFERROR(N36/W36,0) -> 0 | AA36: =IF(OR(U36="",Y36="",Z36=""),"",IF(AND(U36>Y36,-U36<Z36),"Ok","Not Ok"))
A37: =TB_audited!A20 -> Other current asset | D37: =TB_audited!B20 -> 11908 | E37: =TB_audited!C20 -> 130/0210 | F37: =TB_audited!D20 -> BAHRUDIN | G37: =IF($D$8="Interim",TB_audited!G20,TB_audited!E20) -> 0 | H37: =IFERROR(VLOOKUP($A37,RA_result!$B$3:$N$62,11,0),"") | I37: =IFERROR(VLOOKUP($A37,RA_result!$B$3:$N$62,12,0),"") | J37: =IFERROR(VLOOKUP($A37,RA_result!$B$3:$N$62,13,0),"") | M37: 0 | N37: =G37-M37 -> 0 | O37: =IFERROR(VLOOKUP($A37,RA_result!$B$3:$N$62,7,0),"") -> TM | P37: =IFERROR(VLOOKUP($A37,RA_result!$B$3:$N$62,9,0),"") -> L | Q37: =IFERROR(VLOOKUP($A37,RA_result!$B$3:$N$62,10,0),"") | R37: N | S37: =IFERROR(VLOOKUP($A37,RA_result!$B$3:$N$62,4,0),"") -> 1.0535504e+09 | T37: 0.9 | U37: =IFERROR(IF(VLOOKUP($A37,RA_result!$B$3:$N$62,6,0)="",S37*T37,VLOOKUP($A37,RA_result!$B$3:$N$62,6,0)),"") -> 9.4819535e+08 | W37: =IFERROR((S37*30%)/V37,0) -> 0 | X37: =IFERROR(N37/W37,0) -> 0 | AA37: =IF(OR(U37="",Y37="",Z37=""),"",IF(AND(U37>Y37,-U37<Z37),"Ok","Not Ok"))
A38: =TB_audited!A21 -> Other current asset | D38: =TB_audited!B21 -> 11909 | E38: =TB_audited!C21 -> 130/0220 | F38: =TB_audited!D21 -> DEDI RIYADI | G38: =IF($D$8="Interim",TB_audited!G21,TB_audited!E21) -> 0 | H38: =IFERROR(VLOOKUP($A38,RA_result!$B$3:$N$62,11,0),"") | I38: =IFERROR(VLOOKUP($A38,RA_result!$B$3:$N$62,12,0),"") | J38: =IFERROR(VLOOKUP($A38,RA_result!$B$3:$N$62,13,0),"") | M38: 0 | N38: =G38-M38 -> 0 | O38: =IFERROR(VLOOKUP($A38,RA_result!$B$3:$N$62,7,0),"") -> TM | P38: =IFERROR(VLOOKUP($A38,RA_result!$B$3:$N$62,9,0),"") -> L | Q38: =IFERROR(VLOOKUP($A38,RA_result!$B$3:$N$62,10,0),"") | R38: N | S38: =IFERROR(VLOOKUP($A38,RA_result!$B$3:$N$62,4,0),"") -> 1.0535504e+09 | T38: 0.9 | U38: =IFERROR(IF(VLOOKUP($A38,RA_result!$B$3:$N$62,6,0)="",S38*T38,VLOOKUP($A38,RA_result!$B$3:$N$62,6,0)),"") -> 9.4819535e+08 | W38: =IFERROR((S38*30%)/V38,0) -> 0 | X38: =IFERROR(N38/W38,0) -> 0 | AA38: =IF(OR(U38="",Y38="",Z38=""),"",IF(AND(U38>Y38,-U38<Z38),"Ok","Not Ok"))
A39: =TB_audited!A22 -> Other current asset | D39: =TB_audited!B22 -> 11910 | E39: =TB_audited!C22 -> 130/0230 | F39: =TB_audited!D22 -> HARVY WAHYU PERDANA | G39: =IF($D$8="Interim",TB_audited!G22,TB_audited!E22) -> 0 | H39: =IFERROR(VLOOKUP($A39,RA_result!$B$3:$N$62,11,0),"") | I39: =IFERROR(VLOOKUP($A39,RA_result!$B$3:$N$62,12,0),"") | J39: =IFERROR(VLOOKUP($A39,RA_result!$B$3:$N$62,13,0),"") | M39: 0 | N39: =G39-M39 -> 0 | O39: =IFERROR(VLOOKUP($A39,RA_result!$B$3:$N$62,7,0),"") -> TM | P39: =IFERROR(VLOOKUP($A39,RA_result!$B$3:$N$62,9,0),"") -> L | Q39: =IFERROR(VLOOKUP($A39,RA_result!$B$3:$N$62,10,0),"") | R39: N | S39: =IFERROR(VLOOKUP($A39,RA_result!$B$3:$N$62,4,0),"") -> 1.0535504e+09 | T39: 0.9 | U39: =IFERROR(IF(VLOOKUP($A39,RA_result!$B$3:$N$62,6,0)="",S39*T39,VLOOKUP($A39,RA_result!$B$3:$N$62,6,0)),"") -> 9.4819535e+08 | W39: =IFERROR((S39*30%)/V39,0) -> 0 | X39: =IFERROR(N39/W39,0) -> 0 | AA39: =IF(OR(U39="",Y39="",Z39=""),"",IF(AND(U39>Y39,-U39<Z39),"Ok","Not Ok"))
A40: =TB_audited!A23 -> Other current asset | D40: =TB_audited!B23 -> 11911 | E40: =TB_audited!C23 -> 130/0250 | F40: =TB_audited!D23 -> TOMI HARIYANTO | G40: =IF($D$8="Interim",TB_audited!G23,TB_audited!E23) -> 4500000 | H40: =IFERROR(VLOOKUP($A40,RA_result!$B$3:$N$62,11,0),"") | I40: =IFERROR(VLOOKUP($A40,RA_result!$B$3:$N$62,12,0),"") | J40: =IFERROR(VLOOKUP($A40,RA_result!$B$3:$N$62,13,0),"") | M40: 4500000 | N40: =G40-M40 -> 0 | O40: =IFERROR(VLOOKUP($A40,RA_result!$B$3:$N$62,7,0),"") -> TM | P40: =IFERROR(VLOOKUP($A40,RA_result!$B$3:$N$62,9,0),"") -> L | Q40: =IFERROR(VLOOKUP($A40,RA_result!$B$3:$N$62,10,0),"") | R40: N | S40: =IFERROR(VLOOKUP($A40,RA_result!$B$3:$N$62,4,0),"") -> 1.0535504e+09 | T40: 0.9 | U40: =IFERROR(IF(VLOOKUP($A40,RA_result!$B$3:$N$62,6,0)="",S40*T40,VLOOKUP($A40,RA_result!$B$3:$N$62,6,0)),"") -> 9.4819535e+08 | W40: =IFERROR((S40*30%)/V40,0) -> 0 | X40: =IFERROR(N40/W40,0) -> 0 | AA40: =IF(OR(U40="",Y40="",Z40=""),"",IF(AND(U40>Y40,-U40<Z40),"Ok","Not Ok"))
A41: =TB_audited!A24 -> Other current asset | D41: =TB_audited!B24 -> 11912 | E41: =TB_audited!C24 -> 130/0260 | F41: =TB_audited!D24 -> SUHARTOYO | G41: =IF($D$8="Interim",TB_audited!G24,TB_audited!E24) -> 0 | H41: =IFERROR(VLOOKUP($A41,RA_result!$B$3:$N$62,11,0),"") | I41: =IFERROR(VLOOKUP($A41,RA_result!$B$3:$N$62,12,0),"") | J41: =IFERROR(VLOOKUP($A41,RA_result!$B$3:$N$62,13,0),"") | M41: 0 | N41: =G41-M41 -> 0 | O41: =IFERROR(VLOOKUP($A41,RA_result!$B$3:$N$62,7,0),"") -> TM | P41: =IFERROR(VLOOKUP($A41,RA_result!$B$3:$N$62,9,0),"") -> L | Q41: =IFERROR(VLOOKUP($A41,RA_result!$B$3:$N$62,10,0),"") | R41: N | S41: =IFERROR(VLOOKUP($A41,RA_result!$B$3:$N$62,4,0),"") -> 1.0535504e+09 | T41: 0.9 | U41: =IFERROR(IF(VLOOKUP($A41,RA_result!$B$3:$N$62,6,0)="",S41*T41,VLOOKUP($A41,RA_result!$B$3:$N$62,6,0)),"") -> 9.4819535e+08 | W41: =IFERROR((S41*30%)/V41,0) -> 0 | X41: =IFERROR(N41/W41,0) -> 0 | AA41: =IF(OR(U41="",Y41="",Z41=""),"",IF(AND(U41>Y41,-U41<Z41),"Ok","Not Ok"))
A42: =TB_audited!A25 -> Other current asset | D42: =TB_audited!B25 -> 11913 | E42: =TB_audited!C25 -> 140/0050 | F42: =TB_audited!D25 -> IRWAN YUWONO | G42: =IF($D$8="Interim",TB_audited!G25,TB_audited!E25) -> 6600000 | H42: =IFERROR(VLOOKUP($A42,RA_result!$B$3:$N$62,11,0),"") | I42: =IFERROR(VLOOKUP($A42,RA_result!$B$3:$N$62,12,0),"") | J42: =IFERROR(VLOOKUP($A42,RA_result!$B$3:$N$62,13,0),"") | M42: 6600000 | N42: =G42-M42 -> 0 | O42: =IFERROR(VLOOKUP($A42,RA_result!$B$3:$N$62,7,0),"") -> TM | P42: =IFERROR(VLOOKUP($A42,RA_result!$B$3:$N$62,9,0),"") -> L | Q42: =IFERROR(VLOOKUP($A42,RA_result!$B$3:$N$62,10,0),"") | R42: N | S42: =IFERROR(VLOOKUP($A42,RA_result!$B$3:$N$62,4,0),"") -> 1.0535504e+09 | T42: 0.9 | U42: =IFERROR(IF(VLOOKUP($A42,RA_result!$B$3:$N$62,6,0)="",S42*T42,VLOOKUP($A42,RA_result!$B$3:$N$62,6,0)),"") -> 9.4819535e+08 | W42: =IFERROR((S42*30%)/V42,0) -> 0 | X42: =IFERROR(N42/W42,0) -> 0 | AA42: =IF(OR(U42="",Y42="",Z42=""),"",IF(AND(U42>Y42,-U42<Z42),"Ok","Not Ok"))
A43: =TB_audited!A26 -> Other current asset | D43: =TB_audited!B26 -> 11914 | E43: =TB_audited!C26 -> 140/0370 | F43: =TB_audited!D26 -> SUHARTOYO | G43: =IF($D$8="Interim",TB_audited!G26,TB_audited!E26) -> 7100000 | H43: =IFERROR(VLOOKUP($A43,RA_result!$B$3:$N$62,11,0),"") | I43: =IFERROR(VLOOKUP($A43,RA_result!$B$3:$N$62,12,0),"") | J43: =IFERROR(VLOOKUP($A43,RA_result!$B$3:$N$62,13,0),"") | M43: 7100000 | N43: =G43-M43 -> 0 | O43: =IFERROR(VLOOKUP($A43,RA_result!$B$3:$N$62,7,0),"") -> TM | P43: =IFERROR(VLOOKUP($A43,RA_result!$B$3:$N$62,9,0),"") -> L | Q43: =IFERROR(VLOOKUP($A43,RA_result!$B$3:$N$62,10,0),"") | R43: N | S43: =IFERROR(VLOOKUP($A43,RA_result!$B$3:$N$62,4,0),"") -> 1.0535504e+09 | T43: 0.9 | U43: =IFERROR(IF(VLOOKUP($A43,RA_result!$B$3:$N$62,6,0)="",S43*T43,VLOOKUP($A43,RA_result!$B$3:$N$62,6,0)),"") -> 9.4819535e+08 | W43: =IFERROR((S43*30%)/V43,0) -> 0 | X43: =IFERROR(N43/W43,0) -> 0 | AA43: =IF(OR(U43="",Y43="",Z43=""),"",IF(AND(U43>Y43,-U43<Z43),"Ok","Not Ok"))
... A45: =TB_audited!A28 -> Other current asset | D45: =TB_audited!B28 -> 11916 | E45: =TB_audited!C28 -> 140/0503 | F45: =TB_audited!D28 -> ALFI FADLI RUFI AZI | G45: =IF($D$8="Interim",TB_audited!G28,TB_audited!E28) -> 6900000 | H45: =IFERROR(VLOOKUP($A45,RA_result!$B$3:$N$62,11,0),"") | I45: =IFERROR(VLOOKUP($A45,RA_result!$B$3:$N$62,12,0),"") | J45: =IFERROR(VLOOKUP($A45,RA_result!$B$3:$N$62,13,0),"") | M45: 6900000 | N45: =G45-M45 -> 0 | O45: =IFERROR(VLOOKUP($A45,RA_result!$B$3:$N$62,7,0),"") -> TM | P45: =IFERROR(VLOOKUP($A45,RA_result!$B$3:$N$62,9,0),"") -> L | Q45: =IFERROR(VLOOKUP($A45,RA_result!$B$3:$N$62,10,0),"") | R45: N | S45: =IFERROR(VLOOKUP($A45,RA_result!$B$3:$N$62,4,0),"") -> 1.0535504e+09 | T45: 0.9 | U45: =IFERROR(IF(VLOOKUP($A45,RA_result!$B$3:$N$62,6,0)="",S45*T45,VLOOKUP($A45,RA_result!$B$3:$N$62,6,0)),"") -> 9.4819535e+08 | W45: =IFERROR((S45*30%)/V45,0) -> 0 | X45: =IFERROR(N45/W45,0) -> 0 | AA45: =IF(OR(U45="",Y45="",Z45=""),"",IF(AND(U45>Y45,-U45<Z45),"Ok","Not Ok"))
...

Sheet RA_result
A1: RA.120 | C1: 0 | D1: RA.220 | I1: RA.230 | L1: Periksa
A2: Kode | B2: Header | C2: 0 | D2: OM | E2: PM | F2: SM-OM | G2: SM-PM | I2: ASERSI | J2: ROMM | K2: SA | L2: AP | M2: TOD | N2: Saat
A3: Kode | B3: Header | C3: 45657 | D3: OM | E3: PM | F3: SM-OM | G3: SM-PM | H3: PM | I3: ASERSI | J3: ROMM | K3: SA | L3: AP | M3: TOD | N3: Saat
A4: 111 | B4: Cash and cash equivalent | C4: 3.4320162e+10 | D4: 1.505072e+09 | E4: 1.0535504e+09 | H4: M | I4: E V | J4: L | M4: Ya | N4: YE
A5: 112 | B5: Trade receivable | C5: 16281458401 | D5: 1.505072e+09 | E5: 1.0535504e+09 | H5: M | I5: E V | J5: M | M5: Ya | N5: YE
A6: 116 | B6: Inventory | C6: 1.4229503e+10 | D6: 1.505072e+09 | E6: 1.0535504e+09 | H6: M | I6: E V | J6: L | M6: Ya | N6: YE
A7: 117 | B7: Prepayment | C7: 2133021044 | D7: 1.505072e+09 | E7: 1.0535504e+09 | H7: M | I7: E V | J7: M | L7: Ya | M7: Ya | N7: YE
A8: 118 | B8: Prepaid tax | C8: 499052369 | D8: 1.505072e+09 | E8: 1.0535504e+09 | F8: 4.2142016e+08 | G8: 2.9499411e+08 | H8: M | I8: E V | J8: L | M8: Ya | N8: YE
A9: 119 | B9: Other current asset | C9: 35200000 | D9: 1.505072e+09 | E9: 1.0535504e+09 | H9: TM | I9: E V | J9: L
A10: 125 | B10: Fixed asset | C10: 7776927237 | D10: 1.505072e+09 | E10: 1.0535504e+09 | H10: M | I10: E V | J10: L | L10: Ya | M10: Ya | N10: YE
A11: 127 | B11: Intangible asset | C11: 0 | D11: 1.505072e+09 | E11: 1.0535504e+09 | H11: TM | I11: E V | J11: L
A12: 211 | B12: Trade payable | C12: 1.2695742e+10 | D12: 1.505072e+09 | E12: 1.0535504e+09 | H12: M | I12: C V | J12: L | M12: Ya | N12: YE
A13: 212 | B13: Accruals and other payable | C13: 15873194 | D13: 1.505072e+09 | E13: 1.0535504e+09 | H13: TM | I13: C V | J13: L
A14: 216 | B14: Short-term employee benefit liability | C14: 1247188889 | D14: 1.505072e+09 | E14: 1.0535504e+09 | H14: M | I14: C V | J14: L | M14: Ya | N14: YE
A15: 217 | B15: Taxes payable | C15: 501182221 | D15: 1.505072e+09 | E15: 1.0535504e+09 | F15: 4.2142016e+08 | G15: 2.9499411e+08 | H15: M | I15: C V | J15: L | M15: Ya | N15: YE
A16: 229 | B16: Other long-term liability | C16: 2775984576 | D16: 1.505072e+09 | E16: 1.0535504e+09 | H16: M | I16: C V | J16: L | M16: Ya | N16: YE
A17: 311 | B17: Share capital | C17: 10500000000 | D17: 1.505072e+09 | E17: 1.0535504e+09 | H17: M | I17: E V | J17: L | M17: Ya | N17: YE
A18: 332 | B18: Retained earnings – unappropriated | C18: 31480858157 | D18: 1.505072e+09 | E18: 1.0535504e+09 | H18: M | I18: E V | J18: L | M18: Ya | N18: YE
A19: 411 | B19: Revenue | C19: 8.3417567e+10 | D19: 1.505072e+09 | E19: 1.0535504e+09 | H19: M | I19: E A&C | J19: H | M19: Ya | N19: YE
A20: 421 | B20: Interest income | C20: 5.4948148e+08 | D20: 1.505072e+09 | E20: 1.0535504e+09 | F20: 4.2142016e+08 | G20: 2.9499411e+08 | H20: M | I20: E A&C | J20: L | M20: Ya | N20: YE
A21: 422 | B21: Other revenues besides interest income | C21: -1.7123331e+08 | D21: 1.505072e+09 | E21: 1.0535504e+09 | H21: M | I21: C A&C | J21: L | M21: Ya | N21: YE
A22: 511 | B22: Cost of revenue | C22: 5.1089641e+10 | D22: 1.505072e+09 | E22: 1.0535504e+09 | H22: M | I22: C A&C | J22: L | M22: Ya | N22: YE
A23: 521 | B23: Human resources expense | C23: 3418854851 | D23: 1.505072e+09 | E23: 1.0535504e+09 | H23: M | I23: C A&C | J23: L | M23: Ya | N23: YE
A24: 522 | B24: General and administrative expense | C24: 3.8755874e+09 | D24: 1.505072e+09 | E24: 1.0535504e+09 | H24: TM | I24: C A&C | J24: L
A25: 523 | B25: Depreciation and amortization expense | C25: 495378476 | D25: 1.505072e+09 | E25: 1.0535504e+09 | H25: M | I25: C A&C | J25: L | M25: Ya | N25: YE
A26: 532 | B26: Other expenses besides interest expense | C26: 3.4153249e+09 | D26: 1.505072e+09 | E26: 1.0535504e+09 | H26: M | I26: C A&C | J26: L | M26: Ya | N26: YE
A27: 541 | B27: Current tax expense | C27: 5442533360 | D27: 1.505072e+09 | E27: 1.0535504e+09 | H27: M | I27: C A&C | J27: L | M27: Ya | N27: YE
A63: X | B63: X | C63: X | D63: X | E63: X | F63: X | G63: X | H63: X | I63: X | J63: X | K63: X | L63: X | M63: X | N63: X

Sheet TB_audited
A1: Trial Balance | E1: Current | F1: Previous | G1: Interim
A2: header | B2: no_N | C2: no_O | D2: nama_akun | E2: 45657 | F2: 45291 | G2: 45657
A3: Trade receivable | B3: 11201 | C3: 100/0000 | D3: TRADE DEBTORS - IDR | E3: 18567911215 | F3: 22990014172 | G3: 18567911215
A4: Trade receivable | B4: 11202 | C4: 100/0001 | D4: Provision of Allowance Bad Debts | E4: -2286452814 | F4: -1143226407 | G4: -2286452814
A5: Other current asset | B5: 11901 | C5: 105/0010 | D5: YKL ENGINEERING SDN. BHD. (PJS) | E5: 0 | F5: 16000000 | G5: 0
A6: Other current asset | B6: 11902 | C6: 105/0060 | D6: PT. KMT ENGINEERING NUSANTARA (PJS) | E6: 0 | F6: 0 | G6: 0
A7: Cash and cash equivalent | B7: 11101 | C7: 110/0000 | D7: CASH IN HAND | E7: 23836004 | F7: 15160437 | G7: 23836004
A8: Cash and cash equivalent | B8: 11102 | C8: 120/0030 | D8: CASH AT BANK-BCA (2ND) A/C : 764BCA (2ND) A/C : 7640669998 IDR | E8: 21825626 | F8: 993712492 | G8: 21825626
A9: Cash and cash equivalent | B9: 11103 | C9: 120/0040 | D9: CASH AT BANK-BCA (EMG) A/C : 764BCA (EMG) A/C : 7640669599 IDR | E9: 2.487905e+08 | F9: 309372414 | G9: 2.487905e+08
A10: Cash and cash equivalent | B10: 11104 | C10: 120/0050 | D10: CASH AT BANK-MANDIRI A/C : 118003MANDIRI A/C : 1180033355677 IDR | E10: 3.3120579e+10 | F10: 26887905412 | G10: 3.3120579e+10
A11: Cash and cash equivalent | B11: 11105 | C11: 120/0100 | D11: CASH AT BANK-MANDIRI A/C : 1180007MANDIRI A/C : 1180007832388 USD2 | E11: 0 | F11: 0 | G11: 0
A12: Cash and cash equivalent | B12: 11106 | C12: 120/0140 | D12: CASH AT BANK-BNI A/C:855771775 | E12: 905130602 | F12: 897718588 | G12: 905130602
A13: Inventory | B13: 11601 | C13: 126/1000 | D13: INVENTORY-MACHINE | E13: 333000000 | F13: 333000000 | G13: 333000000
A14: Inventory | B14: 11602 | C14: 126/2000 | D14: INVENTORY-SPAREPARTS | E14: 1.3896503e+10 | F14: 9896961465 | G14: 1.3896503e+10
... A128: General and administrative expense | B128: 52230 | C128: 980/0020 | D128: Taxation | E128: 558931077 | F128: 0 | G128: 558931077
A1003: X | B1003: X | C1003: X | D1003: X | E1003: X | F1003: X | G1003: X
